<?xml version="1.0" encoding="utf-8" ?>
<!-- This URDF was automatically created by SolidWorks to URDF Exporter! Originally created by Stephen Brawner (brawner@gmail.com) 
     Commit Version: 1.6.0-4-g7f85cfe  Build Version: 1.6.7995.38578
     For more information, please see http://wiki.ros.org/sw_urdf_exporter -->
<robot name="easyarm_description">
    <link name="world"/>
	<joint name="fixed" type="fixed">
 		 <parent link="world"/>
		 <child link="base_link"/>
	</joint>
    <link name="base_link">
        <inertial>
            <origin xyz="-0.00010017 -0.043183 0.019173" rpy="0 0 0" />
            <mass value="0.28718" />
            <inertia ixx="0.001373" ixy="-5.0799E-09" ixz="-6.523E-15" iyy="0.0003812" iyz="1.6475E-13" izz="0.0017481" />
        </inertial>
        <visual>
            <origin xyz="0 0 0" rpy="0 0 0" />
            <geometry>
                <mesh filename="package://easyarm_description/meshes/base_link.STL" />
            </geometry>
            <material name="">
                <color rgba="0.56471 0.56471 0.56471 1" />
            </material>
        </visual>
        <collision>
            <origin xyz="0 0 0" rpy="0 0 0" />
            <geometry>
                <mesh filename="package://easyarm_description/meshes/base_link.STL" />
            </geometry>
        </collision>
    </link>
    <link name="link1">
        <inertial>
            <origin xyz="0.0014573 0.00059152 0.0027287" rpy="0 0 0" />
            <mass value="0.015583" />
            <inertia ixx="5.6364E-06" ixy="-1.3657E-11" ixz="-1.5297E-07" iyy="5.1391E-06" iyz="-2.0972E-12" izz="1.0016E-05" />
        </inertial>
        <visual>
            <origin xyz="0 0 0" rpy="0 0 0" />
            <geometry>
                <mesh filename="package://easyarm_description/meshes/link1.STL" />
            </geometry>
            <material name="">
                <color rgba="1 1 1 1" />
            </material>
        </visual>
        <collision>
            <origin xyz="0 0 0" rpy="0 0 0" />
            <geometry>
                <mesh filename="package://easyarm_description/meshes/link1.STL" />
            </geometry>
        </collision>
    </link>
    <joint name="joint1" type="revolute">
        <origin xyz="0 0 0.0805" rpy="0 0 0" />
        <parent link="base_link" />
        <child link="link1" />
        <axis xyz="0 0 1" />
        <limit lower="-1.57" upper="1.57" effort="10" velocity="1" />
    </joint>
    <link name="link2">
        <inertial>
            <origin xyz="-1.0327E-06 -0.0515 -0.023674" rpy="0 0 0" />
            <mass value="0.014338" />
            <inertia ixx="1.1814E-05" ixy="-4.7435E-14" ixz="-7.1639E-15" iyy="7.681E-06" iyz="-3.4688E-14" izz="5.5188E-06" />
        </inertial>
        <visual>
            <origin xyz="0 0 0" rpy="0 0 0" />
            <geometry>
                <mesh filename="package://easyarm_description/meshes/link2.STL" />
            </geometry>
            <material name="">
                <color rgba="1 1 1 1" />
            </material>
        </visual>
        <collision>
            <origin xyz="0 0 0" rpy="0 0 0" />
            <geometry>
                <mesh filename="package://easyarm_description/meshes/link2.STL" />
            </geometry>
        </collision>
    </link>
    <joint name="joint2" type="revolute">
        <origin xyz="-0.028 0.00975 0.0155" rpy="-1.5708 0 1.5708" />
        <parent link="link1" />
        <child link="link2" />
        <axis xyz="0 0 1" />
        <limit lower="-1.57" upper="1.57" effort="10" velocity="1" />
    </joint>
    <link name="link3">
        <inertial>
            <origin xyz="-0.0046954 -0.04057 -0.028731" rpy="0 0 0" />
            <mass value="0.015148" />
            <inertia ixx="8.4037E-06" ixy="9.0853E-08" ixz="1.5295E-07" iyy="5.2411E-06" iyz="-4.5315E-12" izz="4.8414E-06" />
        </inertial>
        <visual>
            <origin xyz="0 0 0" rpy="0 0 0" />
            <geometry>
                <mesh filename="package://easyarm_description/meshes/link3.STL" />
            </geometry>
            <material name="">
                <color rgba="1 1 1 1" />
            </material>
        </visual>
        <collision>
            <origin xyz="0 0 0" rpy="0 0 0" />
            <geometry>
                <mesh filename="package://easyarm_description/meshes/link3.STL" />
            </geometry>
        </collision>
    </link>
    <joint name="joint3" type="revolute">
        <origin xyz="0 -0.103 0" rpy="0 0 0" />
        <parent link="link2" />
        <child link="link3" />
        <axis xyz="0 0 1" />
        <limit lower="-1.57" upper="1.57" effort="10" velocity="1" />
    </joint>
    <link name="link4">
        <inertial>
            <origin xyz="0.03437 0.051826 -0.029735" rpy="0 0 0" />
            <mass value="0.029851" />
            <inertia ixx="8.8322E-06" ixy="-6.3709E-07" ixz="-1.472E-07" iyy="4.9673E-06" iyz="4.3872E-08" izz="5.6598E-06" />
        </inertial>
        <visual>
            <origin xyz="0 0 0" rpy="0 0 0" />
            <geometry>
                <mesh filename="package://easyarm_description/meshes/link4.STL" />
            </geometry>
            <material name="">
                <color rgba="1 1 1 1" />
            </material>
        </visual>
        <collision>
            <origin xyz="0 0 0" rpy="0 0 0" />
            <geometry>
                <mesh filename="package://easyarm_description/meshes/link4.STL" />
            </geometry>
        </collision>
    </link>
    <joint name="joint4" type="revolute">
        <origin xyz="-0.0015167 -0.09565 -0.002" rpy="0 0 -1.3739" />
        <parent link="link3" />
        <child link="link4" />
        <axis xyz="0 0 1" />
        <limit lower="-1.57" upper="1.57" effort="10" velocity="1" />
    </joint>
    <link name="grapper">
        <inertial>
            <origin xyz="2.1684E-19 0 0.005" rpy="0 0 0" />
            <mass value="0.0007854" />
            <inertia ixx="1.1454E-08" ixy="1.3786E-25" ixz="4.8385E-25" iyy="1.1454E-08" iyz="-1.0793E-25" izz="9.8175E-09" />
        </inertial>
        <visual>
            <origin xyz="0 0 0" rpy="0 0 0" />
            <geometry>
                <mesh filename="package://easyarm_description/meshes/grapper.STL" />
            </geometry>
            <material name="">
                <color rgba="1 1 1 1" />
            </material>
        </visual>
        <collision>
            <origin xyz="0 0 0" rpy="0 0 0" />
            <geometry>
                <mesh filename="package://easyarm_description/meshes/grapper.STL" />
            </geometry>
        </collision>
    </link>
    <joint name="joint5" type="fixed">
        <origin xyz="0.051784 0.12492 -0.028346" rpy="0.19687 1.5708 0" />
        <parent link="link4" />
        <child link="grapper" />
        <axis xyz="0 0 0" />
    </joint>
    <transmission name="trans_joint1">
        <type>transmission_interface/SimpleTransmission</type>
        <joint name="joint1">
            <hardwareInterface>hardware_interface/PositionJointInterface</hardwareInterface>
        </joint>
        <actuator name="joint1_motor">
            <hardwareInterface>hardware_interface/PositionJointInterface</hardwareInterface>
            <mechanicalReduction>1</mechanicalReduction>
        </actuator>
    </transmission>
    <transmission name="trans_joint2">
        <type>transmission_interface/SimpleTransmission</type>
        <joint name="joint2">
            <hardwareInterface>hardware_interface/PositionJointInterface</hardwareInterface>
        </joint>
        <actuator name="joint2_motor">
            <hardwareInterface>hardware_interface/PositionJointInterface</hardwareInterface>
            <mechanicalReduction>1</mechanicalReduction>
        </actuator>
    </transmission>
    <transmission name="trans_joint3">
        <type>transmission_interface/SimpleTransmission</type>
        <joint name="joint3">
            <hardwareInterface>hardware_interface/PositionJointInterface</hardwareInterface>
        </joint>
        <actuator name="joint3_motor">
            <hardwareInterface>hardware_interface/PositionJointInterface</hardwareInterface>
            <mechanicalReduction>1</mechanicalReduction>
        </actuator>
    </transmission>
    <transmission name="trans_joint4">
        <type>transmission_interface/SimpleTransmission</type>
        <joint name="joint4">
            <hardwareInterface>hardware_interface/PositionJointInterface</hardwareInterface>
        </joint>
        <actuator name="joint4_motor">
            <hardwareInterface>hardware_interface/PositionJointInterface</hardwareInterface>
            <mechanicalReduction>1</mechanicalReduction>
        </actuator>
    </transmission>
    <gazebo>
        <plugin name="gazebo_ros_control" filename="libgazebo_ros_control.so">
            <robotNamespace>/</robotNamespace>
        </plugin>
    </gazebo>
</robot>
